import { runOnEach } from '../runner/hosts'
import { stubNodeActyxosUnreachable, stubNodeHostUnreachable } from '../stubs'
import { isCodeInvalidInput, isCodeNodeUnreachable } from './util'

describe('ax apps', () => {
  describe('ls', () => {
    test('return `ERR_NODE_UNREACHABLE`', async () => {
      const r = await stubNodeHostUnreachable.ax.Apps.Ls()
      expect(isCodeNodeUnreachable(r)).toBe(true)
    })

    test('return `ERR_NODE_UNREACHABLE`', async () => {
      const r = await stubNodeActyxosUnreachable.ax.Apps.Ls()
      expect(isCodeNodeUnreachable(r)).toBe(true)
    })

    test('return empty result if no apps', async () => {
      const responses = await runOnEach([{}, {}], false, (node) => node.ax.Apps.Ls())
      const test = [
        { code: 'OK', result: [] },
        { code: 'OK', result: [] },
      ]
      expect(responses).toMatchObject(test)
    })
  })
  // FIXME: found out why the next test pass but its name does not show up in stdout
  describe('validate', () => {
    test('return `ERR_INVALID_INPUT` if file path does not exist', async () => {
      const response = await stubNodeHostUnreachable.ax.Apps.Validate('foo')
      expect(isCodeInvalidInput(response)).toBe(true)
    })
  })
})
